<?xml version="1.0"?>
<!--
  Left arm module (3 DOF): shoulder pan/lift, elbow flex.
-->
<robot xmlns:xacro="http://www.ros.org/wiki/xacro">
  <xacro:macro name="sensei_arm_left" params="parent">
    <link name="l_shoulder_link">
      <inertial>
        <mass value="0.2"/>
        <origin xyz="0 0 0.02" rpy="0 0 0"/>
        <inertia ixx="0.001" ixy="0" ixz="0" iyy="0.001" iyz="0" izz="0.001"/>
      </inertial>
      <visual>
        <origin xyz="0 0 0.02" rpy="0 0 0"/>
        <geometry>
          <cylinder radius="0.025" length="0.04"/>
        </geometry>
        <material name="arm_blue">
          <color rgba="0.2 0.2 0.8 1.0"/>
        </material>
      </visual>
      <collision>
        <origin xyz="0 0 0.02" rpy="0 0 0"/>
        <geometry>
          <cylinder radius="0.025" length="0.04"/>
        </geometry>
      </collision>
    </link>

    <joint name="l_shoulder_pan" type="revolute">
      <origin xyz="0 0.08 0.11" rpy="0 0 0"/>
      <parent link="${parent}"/>
      <child link="l_shoulder_link"/>
      <axis xyz="0 0 1"/>
      <limit lower="-1.4" upper="1.4" effort="8" velocity="2.0"/>
    </joint>

    <link name="l_upper_arm_link">
      <inertial>
        <mass value="0.2"/>
        <origin xyz="0 0 0.03" rpy="0 0 0"/>
        <inertia ixx="0.001" ixy="0" ixz="0" iyy="0.001" iyz="0" izz="0.001"/>
      </inertial>
      <visual>
        <origin xyz="0 0 0.03" rpy="0 0 0"/>
        <geometry>
          <cylinder radius="0.02" length="0.06"/>
        </geometry>
        <material name="arm_blue">
          <color rgba="0.2 0.2 0.8 1.0"/>
        </material>
      </visual>
      <collision>
        <origin xyz="0 0 0.03" rpy="0 0 0"/>
        <geometry>
          <cylinder radius="0.02" length="0.06"/>
        </geometry>
      </collision>
    </link>

    <joint name="l_shoulder_lift" type="revolute">
      <origin xyz="0 0 0.04" rpy="0 0 0"/>
      <parent link="l_shoulder_link"/>
      <child link="l_upper_arm_link"/>
      <axis xyz="0 1 0"/>
      <limit lower="-1.2" upper="1.2" effort="8" velocity="2.0"/>
    </joint>

    <link name="l_forearm_link">
      <inertial>
        <mass value="0.15"/>
        <origin xyz="0 0 0.025" rpy="0 0 0"/>
        <inertia ixx="0.0008" ixy="0" ixz="0" iyy="0.0008" iyz="0" izz="0.0008"/>
      </inertial>
      <visual>
        <origin xyz="0 0 0.025" rpy="0 0 0"/>
        <geometry>
          <cylinder radius="0.018" length="0.05"/>
        </geometry>
        <material name="arm_blue">
          <color rgba="0.2 0.2 0.8 1.0"/>
        </material>
      </visual>
      <collision>
        <origin xyz="0 0 0.025" rpy="0 0 0"/>
        <geometry>
          <cylinder radius="0.018" length="0.05"/>
        </geometry>
      </collision>
    </link>

    <joint name="l_elbow_flex" type="revolute">
      <origin xyz="0 0 0.06" rpy="0 0 0"/>
      <parent link="l_upper_arm_link"/>
      <child link="l_forearm_link"/>
      <axis xyz="0 1 0"/>
      <limit lower="-2.0" upper="0.0" effort="6" velocity="2.0"/>
    </joint>
  </xacro:macro>
</robot>
